<?xml version="1.0" encoding="utf-8"?>
<!-- This URDF was automatically created by SolidWorks to URDF Exporter! Originally created by Stephen Brawner (brawner@gmail.com) 
     Commit Version: 1.6.0-4-g7f85cfe  Build Version: 1.6.7995.38578
     For more information, please see http://wiki.ros.org/sw_urdf_exporter -->
<robot
  name="4dof_1st">
  <link
    name="base">
    <inertial>
      <origin
        xyz="1.46459065209692E-17 0.0279238800911216 2.10438569532799E-17"
        rpy="0 0 0" />
      <mass
        value="1.01233115660444" />
      <inertia
        ixx="0.00127851826321163"
        ixy="-2.84647285928239E-20"
        ixz="-2.04313611300598E-19"
        iyy="0.00330201153266579"
        iyz="-5.59989405987059E-20"
        izz="0.00254994453490086" />
    </inertial>
    <visual>
      <origin
        xyz="0 0 0"
        rpy="0 0 0" />
      <geometry>
        <mesh
          filename="package://4dof_1st/meshes/base.STL" />
      </geometry>
      <material
        name="clear">
        <color
          rgba="0.3 0.3 0.3 1" />
      </material>
    </visual>
    <collision>
      <origin
        xyz="0 0 0"
        rpy="0 0 0" />
      <geometry>
        <mesh
          filename="package://4dof_1st/meshes/base.STL" />
      </geometry>
    </collision>
  </link>
  <link
    name="L1">
    <inertial>
      <origin
        xyz="6.98379577605036E-08 0.00839921203566611 -0.00011619558777941"
        rpy="0 0 0" />
      <mass
        value="0.109719412381612" />
      <inertia
        ixx="4.04026836034197E-05"
        ixy="-1.24783674052928E-10"
        ixz="-1.48199934122019E-10"
        iyy="5.74445778942386E-05"
        iyz="-1.44657703020893E-07"
        izz="3.7937379436841E-05" />
    </inertial>
    <visual>
      <origin
        xyz="0 0 0"
        rpy="0 0 0" />
      <geometry>
        <mesh
          filename="package://4dof_1st/meshes/L1.STL" />
      </geometry>
      <material
        name="clear">
        <color
          rgba="0.3 0.3 0.3 1" />
      </material>
    </visual>
    <collision>
      <origin
        xyz="0 0 0"
        rpy="0 0 0" />
      <geometry>
        <mesh
          filename="package://4dof_1st/meshes/L1.STL" />
      </geometry>
    </collision>
  </link>
  <joint
    name="base_L1"
    type="continuous">
    <origin
      xyz="0 0 0.06806"
      rpy="1.5707963267949 0 1.5707963267949" />
    <parent
      link="base" />
    <child
      link="L1" />
    <axis
      xyz="0 1 0" />
  </joint>
  <link
    name="L2">
    <inertial>
      <origin
        xyz="0.0702336453115942 0.00389238854048329 -0.0201130596648308"
        rpy="0 0 0" />
      <mass
        value="0.202780167580016" />
      <inertia
        ixx="0.000109799446034618"
        ixy="-3.30138194275749E-06"
        ixz="8.2619647998707E-05"
        iyy="0.000352426504373169"
        iyz="8.08050887748614E-07"
        izz="0.000386493423397687" />
    </inertial>
    <visual>
      <origin
        xyz="0 0 0"
        rpy="0 0 0" />
      <geometry>
        <mesh
          filename="package://4dof_1st/meshes/L2.STL" />
      </geometry>
      <material
        name="gray">
        <color
          rgba="0.55 0.55 0.55 0.8" />
      </material>
    </visual>
    <collision>
      <origin
        xyz="0 0 0"
        rpy="0 0 0" />
      <geometry>
        <mesh
          filename="package://4dof_1st/meshes/L2.STL" />
      </geometry>
    </collision>
  </link>
  <joint
    name="L1_L2"
    type="continuous">
    <origin
      xyz="0 0.04 0"
      rpy="-1.5707963267949 0 1.82825948514324" />
    <parent
      link="L1" />
    <child
      link="L2" />
    <axis
      xyz="0 -1 0" />
  </joint>
  <link
    name="L3">
    <inertial>
      <origin
        xyz="-0.0478479592653754 0.00515392784575905 0.0519819866111054"
        rpy="0 0 0" />
      <mass
        value="0.147186775685883" />
      <inertia
        ixx="0.000138624780944488"
        ixy="4.37801584099522E-06"
        ixz="7.10053754036743E-05"
        iyy="0.000163287060061744"
        iyz="-4.40680894568525E-06"
        izz="0.000111799281194118" />
    </inertial>
    <visual>
      <origin
        xyz="0 0 0"
        rpy="0 0 0" />
      <geometry>
        <mesh
          filename="package://4dof_1st/meshes/L3.STL" />
      </geometry>
      <material
        name="gray">
        <color
          rgba="0.55 0.55 0.55 0.8" />
      </material>
    </visual>
    <collision>
      <origin
        xyz="0 0 0"
        rpy="0 0 0" />
      <geometry>
        <mesh
          filename="package://4dof_1st/meshes/L3.STL" />
      </geometry>
    </collision>
  </link>
  <joint
    name="L2_L3"
    type="continuous">
    <origin
      xyz="0.123232487432328 0 -0.062343357033776"
      rpy="3.14159265358979 -0.92718462077581 -3.14159265358979" />
    <parent
      link="L2" />
    <child
      link="L3" />
    <axis
      xyz="0 -1 0" />
  </joint>
  <link
    name="L4">
    <inertial>
      <origin
        xyz="0.000535223217596727 1.02410807403808E-06 0.0300122413358316"
        rpy="0 0 0" />
      <mass
        value="0.0347795552224983" />
      <inertia
        ixx="1.20189725985311E-05"
        ixy="-3.6324844596862E-11"
        ixz="1.06433575237549E-07"
        iyy="1.8701961839349E-05"
        iyz="-2.33290064173088E-12"
        izz="9.31854675173955E-06" />
    </inertial>
    <visual>
      <origin
        xyz="0 0 0"
        rpy="0 0 0" />
      <geometry>
        <mesh
          filename="package://4dof_1st/meshes/L4.STL" />
      </geometry>
      <material
        name="gray">
        <color
          rgba="0.55 0.55 0.55 0.8" />
      </material>
    </visual>
    <collision>
      <origin
        xyz="0 0 0"
        rpy="0 0 0" />
      <geometry>
        <mesh
          filename="package://4dof_1st/meshes/L4.STL" />
      </geometry>
    </collision>
  </link>
  <joint
    name="L3_L4"
    type="continuous">
    <origin
      xyz="-0.0955215832350811 0 0.108970341085377"
      rpy="-0.719726043206436 0 1.5707963267949" />
    <parent
      link="L3" />
    <child
      link="L4" />
    <axis
      xyz="-1 0 0" />
  </joint>
</robot>